=== Docker Run Log for 1771937 ===
Started at: Mi 29. Okt 12:27:18 CET 2025

[2025-10-29 12:27:27] START: Running container for 1771937
[2025-10-29 12:27:27] SUCCESS: Container 1b4a60b1550334e648810d11eba8b3d229328bf55cb51c9ea8904b758216fbc9 started for 1771937
=== Container logs for 1771937 ===
Traceback (most recent call last):
  File "/snippet.py", line 3, in <module>
    from django.contrib.gis.db.models import GeometryField
  File "/usr/local/lib/python3.11/site-packages/django/contrib/gis/db/models/__init__.py", line 3, in <module>
    import django.contrib.gis.db.models.functions  # NOQA
    ^^^^^^^^^^^^^^^^^^^^^^^^^^^^^^^^^^^^^^^^^^^^^
  File "/usr/local/lib/python3.11/site-packages/django/contrib/gis/db/models/functions.py", line 3, in <module>
    from django.contrib.gis.db.models.fields import BaseSpatialField, GeometryField
  File "/usr/local/lib/python3.11/site-packages/django/contrib/gis/db/models/fields.py", line 3, in <module>
    from django.contrib.gis import forms, gdal
  File "/usr/local/lib/python3.11/site-packages/django/contrib/gis/forms/__init__.py", line 3, in <module>
    from .fields import (  # NOQA
  File "/usr/local/lib/python3.11/site-packages/django/contrib/gis/forms/fields.py", line 2, in <module>
    from django.contrib.gis.gdal import GDALException
  File "/usr/local/lib/python3.11/site-packages/django/contrib/gis/gdal/__init__.py", line 29, in <module>
    from django.contrib.gis.gdal.datasource import DataSource
  File "/usr/local/lib/python3.11/site-packages/django/contrib/gis/gdal/datasource.py", line 40, in <module>
    from django.contrib.gis.gdal.driver import Driver
  File "/usr/local/lib/python3.11/site-packages/django/contrib/gis/gdal/driver.py", line 5, in <module>
    from django.contrib.gis.gdal.prototypes import ds as capi
  File "/usr/local/lib/python3.11/site-packages/django/contrib/gis/gdal/prototypes/ds.py", line 10, in <module>
    from django.contrib.gis.gdal.libgdal import lgdal
  File "/usr/local/lib/python3.11/site-packages/django/contrib/gis/gdal/libgdal.py", line 64, in <module>
    raise ImproperlyConfigured(
django.core.exceptions.ImproperlyConfigured: Could not find the GDAL library (tried "gdal", "GDAL", "gdal3.10.0", "gdal3.9.0", "gdal3.8.0", "gdal3.7.0", "gdal3.6.0", "gdal3.5.0", "gdal3.4.0", "gdal3.3.0", "gdal3.2.0", "gdal3.1.0"). Is GDAL installed? If it is, try setting GDAL_LIBRARY_PATH in your settings.
=== End of logs for 1771937 ===
[2025-10-29 12:27:29] INFO: Container 1b4a60b1550334e648810d11eba8b3d229328bf55cb51c9ea8904b758216fbc9 has stopped
