=== Docker Run Log for 9bb9eaea2523cd2144cf959f48a14194 ===
Started at: Mi 29. Okt 18:39:14 CET 2025

[2025-10-29 18:39:25] START: Running container for 9bb9eaea2523cd2144cf959f48a14194
[2025-10-29 18:39:26] SUCCESS: Container c134fc2e4935cbf9c46b789504daca0fc30742e823bbc2d5c8056bfe1cac8371 started for 9bb9eaea2523cd2144cf959f48a14194
=== Container logs for 9bb9eaea2523cd2144cf959f48a14194 ===
Traceback (most recent call last):
  File "/snippet.py", line 2, in <module>
    from django.contrib.auth.models import AnonymousUser
  File "/usr/local/lib/python3.11/site-packages/django/contrib/auth/models.py", line 5, in <module>
    from django.contrib.auth.base_user import AbstractBaseUser, BaseUserManager
  File "/usr/local/lib/python3.11/site-packages/django/contrib/auth/base_user.py", line 43, in <module>
    class AbstractBaseUser(models.Model):
  File "/usr/local/lib/python3.11/site-packages/django/db/models/base.py", line 131, in __new__
    app_config = apps.get_containing_app_config(module)
                 ^^^^^^^^^^^^^^^^^^^^^^^^^^^^^^^^^^^^^^
  File "/usr/local/lib/python3.11/site-packages/django/apps/registry.py", line 260, in get_containing_app_config
    self.check_apps_ready()
  File "/usr/local/lib/python3.11/site-packages/django/apps/registry.py", line 137, in check_apps_ready
    settings.INSTALLED_APPS
  File "/usr/local/lib/python3.11/site-packages/django/conf/__init__.py", line 81, in __getattr__
    self._setup(name)
  File "/usr/local/lib/python3.11/site-packages/django/conf/__init__.py", line 61, in _setup
    raise ImproperlyConfigured(
django.core.exceptions.ImproperlyConfigured: Requested setting INSTALLED_APPS, but settings are not configured. You must either define the environment variable DJANGO_SETTINGS_MODULE or call settings.configure() before accessing settings.
=== End of logs for 9bb9eaea2523cd2144cf959f48a14194 ===
[2025-10-29 18:39:28] INFO: Container c134fc2e4935cbf9c46b789504daca0fc30742e823bbc2d5c8056bfe1cac8371 has stopped
